[*] Running ...
[*] Dataset loaded: /home/dokhanhnam1199/QD/problems/tsp_aco/dataset/train50_dataset.npy with 5 instances.
/home/dokhanhnam1199/QD/problems/tsp_aco/gpt.py:25: RuntimeWarning: invalid value encountered in multiply
  # Adjust based on node "degree" within a certain radius (number of nearby cities)
Traceback (most recent call last):
  File "/home/dokhanhnam1199/QD/problems/tsp_aco/eval.py", line 53, in <module>
    obj = solve(node_pos)
  File "/home/dokhanhnam1199/QD/problems/tsp_aco/eval.py", line 29, in solve
    obj = aco.run(N_ITERATIONS)
  File "/home/dokhanhnam1199/.local/lib/python3.10/site-packages/torch/utils/_contextlib.py", line 116, in decorate_context
    return func(*args, **kwargs)
  File "/home/dokhanhnam1199/QD/problems/tsp_aco/aco.py", line 34, in run
    paths = self.gen_path(require_prob=False)
  File "/home/dokhanhnam1199/QD/problems/tsp_aco/aco.py", line 92, in gen_path
    actions, log_probs = self.pick_move(prev, mask, require_prob)
  File "/home/dokhanhnam1199/QD/problems/tsp_aco/aco.py", line 114, in pick_move
    dist = Categorical(dist)
  File "/home/dokhanhnam1199/.local/lib/python3.10/site-packages/torch/distributions/categorical.py", line 73, in __init__
    super().__init__(batch_shape, validate_args=validate_args)
  File "/home/dokhanhnam1199/.local/lib/python3.10/site-packages/torch/distributions/distribution.py", line 72, in __init__
    raise ValueError(
ValueError: Expected parameter probs (Tensor of shape (30, 50)) of distribution Categorical(probs: torch.Size([30, 50])) to satisfy the constraint Simplex(), but found invalid values:
tensor([[nan, nan, nan,  ..., nan, nan, nan],
        [nan, nan, nan,  ..., nan, nan, nan],
        [nan, nan, nan,  ..., nan, nan, nan],
        ...,
        [nan, nan, nan,  ..., nan, nan, nan],
        [nan, nan, nan,  ..., nan, nan, nan],
        [nan, nan, nan,  ..., nan, nan, nan]], dtype=torch.float64)
11
1
131.76952268336282
