[*] Running ...
[*] Dataset loaded: /home/dokhanhnam1199/QD/problems/cvrp_aco/dataset/train50_dataset.npy with 10 instances.
[*] Instance 0: 12.533646466791787
Traceback (most recent call last):
  File "/home/dokhanhnam1199/QD/problems/cvrp_aco/eval.py", line 60, in <module>
    obj = solve(node_pos, demand)
  File "/home/dokhanhnam1199/QD/problems/cvrp_aco/eval.py", line 28, in solve
    heu = heuristics(dist_mat.copy(), node_pos.copy(), demand.copy(), CAPACITY) + 1e-9
  File "/home/dokhanhnam1199/QD/problems/cvrp_aco/gpt.py", line 76, in heuristics_v2
    # Further refine by considering proximity to the depot
  File "/home/dokhanhnam1199/.local/lib/python3.10/site-packages/numpy/lib/_function_base_impl.py", line 4273, in percentile
    return _quantile_unchecked(
  File "/home/dokhanhnam1199/.local/lib/python3.10/site-packages/numpy/lib/_function_base_impl.py", line 4550, in _quantile_unchecked
    return _ureduce(a,
  File "/home/dokhanhnam1199/.local/lib/python3.10/site-packages/numpy/lib/_function_base_impl.py", line 3894, in _ureduce
    r = func(a, **kwargs)
  File "/home/dokhanhnam1199/.local/lib/python3.10/site-packages/numpy/lib/_function_base_impl.py", line 4727, in _quantile_ureduce_func
    result = _quantile(arr,
  File "/home/dokhanhnam1199/.local/lib/python3.10/site-packages/numpy/lib/_function_base_impl.py", line 4849, in _quantile
    slices_having_nans = np.isnan(arr[-1, ...])
IndexError: index -1 is out of bounds for axis 0 with size 0
41
10
549.8803636380671
